Workbook

Sheet Parameters
A1: SaaS ROI Model · B2C AI Image Generation · US Market · v3
A2: Parameter | B2: Pessimistic | C2: Base Case | D2: Optimistic | E2: Notes / Market Benchmark
A3: ── ONE-TIME COSTS
A4: Setup / Launch Cost ($) | B4: 3000 | C4: 2000 | D4: 1000 | E4: Pre-build micro-team. Figma, domain, infra setup
A5: ── MONTHLY FIXED COSTS (step-up by users — see Fixed_Cost_USD formula)
A6: Fixed Cost: 0–100 users ($/mo) | B6: 1000 | C6: 1000 | D6: 1000 | E6: Solo founder + basic infra
A7: Fixed Cost: 101–500 users ($/mo) | B7: 2000 | C7: 1500 | D7: 2000 | E7: Part-time hire or upgraded infra
A8: Fixed Cost: 501–2000 users ($/mo) | B8: 4000 | C8: 4000 | D8: 4000 | E8: Second person + scaling infra
A9: Fixed Cost: 2001–10000 users ($/mo) | B9: 8000 | C9: 8000 | D9: 8000 | E9: Small team (3–4 people)
A10: Fixed Cost: 10000+ users ($/mo) | B10: 15000 | C10: 11000 | D10: 11000 | E10: Ops + eng + support team
A11: ── MARKETING MODEL
A12: Marketing % of Revenue | B12: 0.25 | C12: 0.35 | D12: 0.45 | E12: B2C SaaS benchmark: 25–45% early stage
A13: Minimum Marketing Floor ($/mo) | B13: 300 | C13: 600 | D13: 800 | E13: Guarantees growth even at near-zero revenue
A14: CAC — Cost per Acquired User ($) | B14: 90 | C14: 60 | D14: 55 | E14: Pess=$120 no PLG. Base=$70 new brand. Opti=$35 strong PLG
A15: ── USER ACQUISITION
A16: Organic Growth Rate (%/mo) | B16: 0.01 | C16: 0.03 | D16: 0.04 | E16: % of paid base added organically
A17: Monthly Churn Rate | B17: 0.09 | C17: 0.06 | D17: 0.04 | E17: B2C AI norm: 5–10%/mo
A18: Initial Paid Users (Month 0) | B18: 0 | C18: 0 | D18: 0 | E18: Pre-launch = 0
A19: ── AI / LLM COSTS
A20: LLM / API Cost per User/mo ($) | B20: 8 | C20: 7 | D20: 6 | E20: Pess=$10 updated. Base=$8 updated. Opti=$6 own infra/caching
A21: ── REVENUE
A22: ARPU — Monthly per Paid User ($) | B22: 15 | C22: 23 | D22: 29 | E22: Pess=$15. Base=$19. Opti=$29 prosumer
A23: ── PROJECTION
A24: Projection Horizon (months) | B24: 36 | C24: 36 | D24: 36 | E24: Extended to 36 months
A26: Fixed Cost tiers are the same across all scenarios (only LLM, CAC, ARPU, churn differ by scenario). Change tier values above to update all scenarios simultaneously.
A27: 🔵 Blue = input (change freely) | Black = formula | Green = link from Parameters

Sheet Monthly_Data
A1: Month | B1: Period_Label | C1: Scenario | D1: Users_Paid | E1: Users_New_Paid | F1: Users_New_Organic | G1: Users_Churned | H1: Revenue_USD | I1: Marketing_USD | J1: LLM_Cost_USD | K1: Fixed_Cost_USD | L1: Total_Cost_USD | M1: Gross_Profit_USD | N1: Monthly_PnL_USD | O1: Cumulative_PnL_USD | P1: Gross_Margin_Pct | Q1: Net_Margin_Pct | R1: ARPU_USD | S1: LLM_Per_User_USD | T1: CAC_USD | U1: LTV_USD | V1: CAC_Payback_Mo | W1: LTV_CAC_Ratio | X1: Breakeven_Flag
A2: 1 | B2: M01 | C2: Pessimistic | D2: =MAX(0,Parameters!$B$18+E2+F2-G2) -> 3 | E2: =ROUND(I2/Parameters!$B$14,0) -> 3 | F2: =ROUND(Parameters!$B$18*Parameters!$B$16,0) -> 0 | G2: =ROUND(Parameters!$B$18*Parameters!$B$17,0) -> 0 | H2: =D2*Parameters!$B$22 -> 45 | I2: =MAX(Parameters!$B$13,0) -> 300 | J2: =D2*Parameters!$B$20 -> 24 | K2: =IF(D2<=100,Parameters!$B$6,IF(D2<=500,Parameters!$B$7,IF(D2<=2000,Parameters!$B$8,IF(D2<=10000,Parameters!$B$9,Parameters!$B$10)))) -> 1000 | L2: =I2+J2+K2 -> 1324 | M2: =H2-J2 -> 21 | N2: =H2-L2 -> -1279 | O2: =N2-Parameters!$B$4 -> -4279 | P2: =IF(H2<>0,M2/H2,0) -> 0.46666667 | Q2: =IF(H2<>0,N2/H2,0) -> -28.422222 | R2: =Parameters!$B$22 -> 15 | S2: =Parameters!$B$20 -> 8 | T2: =Parameters!$B$14 -> 90 | U2: =IF(Parameters!$B$17<>0,(Parameters!$B$22-Parameters!$B$20)/Parameters!$B$17,0) -> 77.777778 | V2: =IF((Parameters!$B$22-Parameters!$B$20)>0,Parameters!$B$14/(Parameters!$B$22-Parameters!$B$20),999) -> 12.857143 | W2: =IF(Parameters!$B$14<>0,IF(Parameters!$B$17<>0,(Parameters!$B$22-Parameters!$B$20)/(Parameters!$B$17*Parameters!$B$14),0),0) -> 0.86419753 | X2: =IF(O2>=0,1,0) -> 0
A3: 2 | B3: M02 | C3: Pessimistic | D3: =MAX(0,D2+E3+F3-G3) -> 6 | E3: =ROUND(I3/Parameters!$B$14,0) -> 3 | F3: =ROUND(D2*Parameters!$B$16,0) -> 0 | G3: =ROUND(D2*Parameters!$B$17,0) -> 0 | H3: =D3*Parameters!$B$22 -> 90 | I3: =MAX(Parameters!$B$13,H2*Parameters!$B$12) -> 300 | J3: =D3*Parameters!$B$20 -> 48 | K3: =IF(D3<=100,Parameters!$B$6,IF(D3<=500,Parameters!$B$7,IF(D3<=2000,Parameters!$B$8,IF(D3<=10000,Parameters!$B$9,Parameters!$B$10)))) -> 1000 | L3: =I3+J3+K3 -> 1348 | M3: =H3-J3 -> 42 | N3: =H3-L3 -> -1258 | O3: =O2+N3 -> -5537 | P3: =IF(H3<>0,M3/H3,0) -> 0.46666667 | Q3: =IF(H3<>0,N3/H3,0) -> -13.977778 | R3: =Parameters!$B$22 -> 15 | S3: =Parameters!$B$20 -> 8 | T3: =Parameters!$B$14 -> 90 | U3: =IF(Parameters!$B$17<>0,(Parameters!$B$22-Parameters!$B$20)/Parameters!$B$17,0) -> 77.777778 | V3: =IF((Parameters!$B$22-Parameters!$B$20)>0,Parameters!$B$14/(Parameters!$B$22-Parameters!$B$20),999) -> 12.857143 | W3: =IF(Parameters!$B$14<>0,IF(Parameters!$B$17<>0,(Parameters!$B$22-Parameters!$B$20)/(Parameters!$B$17*Parameters!$B$14),0),0) -> 0.86419753 | X3: =IF(O3>=0,1,0) -> 0
A4: 3 | B4: M03 | C4: Pessimistic | D4: =MAX(0,D3+E4+F4-G4) -> 8 | E4: =ROUND(I4/Parameters!$B$14,0) -> 3 | F4: =ROUND(D3*Parameters!$B$16,0) -> 0 | G4: =ROUND(D3*Parameters!$B$17,0) -> 1 | H4: =D4*Parameters!$B$22 -> 120 | I4: =MAX(Parameters!$B$13,H3*Parameters!$B$12) -> 300 | J4: =D4*Parameters!$B$20 -> 64 | K4: =IF(D4<=100,Parameters!$B$6,IF(D4<=500,Parameters!$B$7,IF(D4<=2000,Parameters!$B$8,IF(D4<=10000,Parameters!$B$9,Parameters!$B$10)))) -> 1000 | L4: =I4+J4+K4 -> 1364 | M4: =H4-J4 -> 56 | N4: =H4-L4 -> -1244 | O4: =O3+N4 -> -6781 | P4: =IF(H4<>0,M4/H4,0) -> 0.46666667 | Q4: =IF(H4<>0,N4/H4,0) -> -10.366667 | R4: =Parameters!$B$22 -> 15 | S4: =Parameters!$B$20 -> 8 | T4: =Parameters!$B$14 -> 90 | U4: =IF(Parameters!$B$17<>0,(Parameters!$B$22-Parameters!$B$20)/Parameters!$B$17,0) -> 77.777778 | V4: =IF((Parameters!$B$22-Parameters!$B$20)>0,Parameters!$B$14/(Parameters!$B$22-Parameters!$B$20),999) -> 12.857143 | W4: =IF(Parameters!$B$14<>0,IF(Parameters!$B$17<>0,(Parameters!$B$22-Parameters!$B$20)/(Parameters!$B$17*Parameters!$B$14),0),0) -> 0.86419753 | X4: =IF(O4>=0,1,0) -> 0
A5: 4 | B5: M04 | C5: Pessimistic | D5: =MAX(0,D4+E5+F5-G5) -> 10 | E5: =ROUND(I5/Parameters!$B$14,0) -> 3 | F5: =ROUND(D4*Parameters!$B$16,0) -> 0 | G5: =ROUND(D4*Parameters!$B$17,0) -> 1 | H5: =D5*Parameters!$B$22 -> 150 | I5: =MAX(Parameters!$B$13,H4*Parameters!$B$12) -> 300 | J5: =D5*Parameters!$B$20 -> 80 | K5: =IF(D5<=100,Parameters!$B$6,IF(D5<=500,Parameters!$B$7,IF(D5<=2000,Parameters!$B$8,IF(D5<=10000,Parameters!$B$9,Parameters!$B$10)))) -> 1000 | L5: =I5+J5+K5 -> 1380 | M5: =H5-J5 -> 70 | N5: =H5-L5 -> -1230 | O5: =O4+N5 -> -8011 | P5: =IF(H5<>0,M5/H5,0) -> 0.46666667 | Q5: =IF(H5<>0,N5/H5,0) -> -8.2 | R5: =Parameters!$B$22 -> 15 | S5: =Parameters!$B$20 -> 8 | T5: =Parameters!$B$14 -> 90 | U5: =IF(Parameters!$B$17<>0,(Parameters!$B$22-Parameters!$B$20)/Parameters!$B$17,0) -> 77.777778 | V5: =IF((Parameters!$B$22-Parameters!$B$20)>0,Parameters!$B$14/(Parameters!$B$22-Parameters!$B$20),999) -> 12.857143 | W5: =IF(Parameters!$B$14<>0,IF(Parameters!$B$17<>0,(Parameters!$B$22-Parameters!$B$20)/(Parameters!$B$17*Parameters!$B$14),0),0) -> 0.86419753 | X5: =IF(O5>=0,1,0) -> 0
A6: 5 | B6: M05 | C6: Pessimistic | D6: =MAX(0,D5+E6+F6-G6) -> 12 | E6: =ROUND(I6/Parameters!$B$14,0) -> 3 | F6: =ROUND(D5*Parameters!$B$16,0) -> 0 | G6: =ROUND(D5*Parameters!$B$17,0) -> 1 | H6: =D6*Parameters!$B$22 -> 180 | I6: =MAX(Parameters!$B$13,H5*Parameters!$B$12) -> 300 | J6: =D6*Parameters!$B$20 -> 96 | K6: =IF(D6<=100,Parameters!$B$6,IF(D6<=500,Parameters!$B$7,IF(D6<=2000,Parameters!$B$8,IF(D6<=10000,Parameters!$B$9,Parameters!$B$10)))) -> 1000 | L6: =I6+J6+K6 -> 1396 | M6: =H6-J6 -> 84 | N6: =H6-L6 -> -1216 | O6: =O5+N6 -> -9227 | P6: =IF(H6<>0,M6/H6,0) -> 0.46666667 | Q6: =IF(H6<>0,N6/H6,0) -> -6.7555556 | R6: =Parameters!$B$22 -> 15 | S6: =Parameters!$B$20 -> 8 | T6: =Parameters!$B$14 -> 90 | U6: =IF(Parameters!$B$17<>0,(Parameters!$B$22-Parameters!$B$20)/Parameters!$B$17,0) -> 77.777778 | V6: =IF((Parameters!$B$22-Parameters!$B$20)>0,Parameters!$B$14/(Parameters!$B$22-Parameters!$B$20),999) -> 12.857143 | W6: =IF(Parameters!$B$14<>0,IF(Parameters!$B$17<>0,(Parameters!$B$22-Parameters!$B$20)/(Parameters!$B$17*Parameters!$B$14),0),0) -> 0.86419753 | X6: =IF(O6>=0,1,0) -> 0
A7: 6 | B7: M06 | C7: Pessimistic | D7: =MAX(0,D6+E7+F7-G7) -> 14 | E7: =ROUND(I7/Parameters!$B$14,0) -> 3 | F7: =ROUND(D6*Parameters!$B$16,0) -> 0 | G7: =ROUND(D6*Parameters!$B$17,0) -> 1 | H7: =D7*Parameters!$B$22 -> 210 | I7: =MAX(Parameters!$B$13,H6*Parameters!$B$12) -> 300 | J7: =D7*Parameters!$B$20 -> 112 | K7: =IF(D7<=100,Parameters!$B$6,IF(D7<=500,Parameters!$B$7,IF(D7<=2000,Parameters!$B$8,IF(D7<=10000,Parameters!$B$9,Parameters!$B$10)))) -> 1000 | L7: =I7+J7+K7 -> 1412 | M7: =H7-J7 -> 98 | N7: =H7-L7 -> -1202 | O7: =O6+N7 -> -10429 | P7: =IF(H7<>0,M7/H7,0) -> 0.46666667 | Q7: =IF(H7<>0,N7/H7,0) -> -5.7238095 | R7: =Parameters!$B$22 -> 15 | S7: =Parameters!$B$20 -> 8 | T7: =Parameters!$B$14 -> 90 | U7: =IF(Parameters!$B$17<>0,(Parameters!$B$22-Parameters!$B$20)/Parameters!$B$17,0) -> 77.777778 | V7: =IF((Parameters!$B$22-Parameters!$B$20)>0,Parameters!$B$14/(Parameters!$B$22-Parameters!$B$20),999) -> 12.857143 | W7: =IF(Parameters!$B$14<>0,IF(Parameters!$B$17<>0,(Parameters!$B$22-Parameters!$B$20)/(Parameters!$B$17*Parameters!$B$14),0),0) -> 0.86419753 | X7: =IF(O7>=0,1,0) -> 0
A8: 7 | B8: M07 | C8: Pessimistic | D8: =MAX(0,D7+E8+F8-G8) -> 16 | E8: =ROUND(I8/Parameters!$B$14,0) -> 3 | F8: =ROUND(D7*Parameters!$B$16,0) -> 0 | G8: =ROUND(D7*Parameters!$B$17,0) -> 1 | H8: =D8*Parameters!$B$22 -> 240 | I8: =MAX(Parameters!$B$13,H7*Parameters!$B$12) -> 300 | J8: =D8*Parameters!$B$20 -> 128 | K8: =IF(D8<=100,Parameters!$B$6,IF(D8<=500,Parameters!$B$7,IF(D8<=2000,Parameters!$B$8,IF(D8<=10000,Parameters!$B$9,Parameters!$B$10)))) -> 1000 | L8: =I8+J8+K8 -> 1428 | M8: =H8-J8 -> 112 | N8: =H8-L8 -> -1188 | O8: =O7+N8 -> -11617 | P8: =IF(H8<>0,M8/H8,0) -> 0.46666667 | Q8: =IF(H8<>0,N8/H8,0) -> -4.95 | R8: =Parameters!$B$22 -> 15 | S8: =Parameters!$B$20 -> 8 | T8: =Parameters!$B$14 -> 90 | U8: =IF(Parameters!$B$17<>0,(Parameters!$B$22-Parameters!$B$20)/Parameters!$B$17,0) -> 77.777778 | V8: =IF((Parameters!$B$22-Parameters!$B$20)>0,Parameters!$B$14/(Parameters!$B$22-Parameters!$B$20),999) -> 12.857143 | W8: =IF(Parameters!$B$14<>0,IF(Parameters!$B$17<>0,(Parameters!$B$22-Parameters!$B$20)/(Parameters!$B$17*Parameters!$B$14),0),0) -> 0.86419753 | X8: =IF(O8>=0,1,0) -> 0
A9: 8 | B9: M08 | C9: Pessimistic | D9: =MAX(0,D8+E9+F9-G9) -> 18 | E9: =ROUND(I9/Parameters!$B$14,0) -> 3 | F9: =ROUND(D8*Parameters!$B$16,0) -> 0 | G9: =ROUND(D8*Parameters!$B$17,0) -> 1 | H9: =D9*Parameters!$B$22 -> 270 | I9: =MAX(Parameters!$B$13,H8*Parameters!$B$12) -> 300 | J9: =D9*Parameters!$B$20 -> 144 | K9: =IF(D9<=100,Parameters!$B$6,IF(D9<=500,Parameters!$B$7,IF(D9<=2000,Parameters!$B$8,IF(D9<=10000,Parameters!$B$9,Parameters!$B$10)))) -> 1000 | L9: =I9+J9+K9 -> 1444 | M9: =H9-J9 -> 126 | N9: =H9-L9 -> -1174 | O9: =O8+N9 -> -12791 | P9: =IF(H9<>0,M9/H9,0) -> 0.46666667 | Q9: =IF(H9<>0,N9/H9,0) -> -4.3481481 | R9: =Parameters!$B$22 -> 15 | S9: =Parameters!$B$20 -> 8 | T9: =Parameters!$B$14 -> 90 | U9: =IF(Parameters!$B$17<>0,(Parameters!$B$22-Parameters!$B$20)/Parameters!$B$17,0) -> 77.777778 | V9: =IF((Parameters!$B$22-Parameters!$B$20)>0,Parameters!$B$14/(Parameters!$B$22-Parameters!$B$20),999) -> 12.857143 | W9: =IF(Parameters!$B$14<>0,IF(Parameters!$B$17<>0,(Parameters!$B$22-Parameters!$B$20)/(Parameters!$B$17*Parameters!$B$14),0),0) -> 0.86419753 | X9: =IF(O9>=0,1,0) -> 0
A10: 9 | B10: M09 | C10: Pessimistic | D10: =MAX(0,D9+E10+F10-G10) -> 19 | E10: =ROUND(I10/Parameters!$B$14,0) -> 3 | F10: =ROUND(D9*Parameters!$B$16,0) -> 0 | G10: =ROUND(D9*Parameters!$B$17,0) -> 2 | H10: =D10*Parameters!$B$22 -> 285 | I10: =MAX(Parameters!$B$13,H9*Parameters!$B$12) -> 300 | J10: =D10*Parameters!$B$20 -> 152 | K10: =IF(D10<=100,Parameters!$B$6,IF(D10<=500,Parameters!$B$7,IF(D10<=2000,Parameters!$B$8,IF(D10<=10000,Parameters!$B$9,Parameters!$B$10)))) -> 1000 | L10: =I10+J10+K10 -> 1452 | M10: =H10-J10 -> 133 | N10: =H10-L10 -> -1167 | O10: =O9+N10 -> -13958 | P10: =IF(H10<>0,M10/H10,0) -> 0.46666667 | Q10: =IF(H10<>0,N10/H10,0) -> -4.0947368 | R10: =Parameters!$B$22 -> 15 | S10: =Parameters!$B$20 -> 8 | T10: =Parameters!$B$14 -> 90 | U10: =IF(Parameters!$B$17<>0,(Parameters!$B$22-Parameters!$B$20)/Parameters!$B$17,0) -> 77.777778 | V10: =IF((Parameters!$B$22-Parameters!$B$20)>0,Parameters!$B$14/(Parameters!$B$22-Parameters!$B$20),999) -> 12.857143 | W10: =IF(Parameters!$B$14<>0,IF(Parameters!$B$17<>0,(Parameters!$B$22-Parameters!$B$20)/(Parameters!$B$17*Parameters!$B$14),0),0) -> 0.86419753 | X10: =IF(O10>=0,1,0) -> 0
A11: 10 | B11: M10 | C11: Pessimistic | D11: =MAX(0,D10+E11+F11-G11) -> 20 | E11: =ROUND(I11/Parameters!$B$14,0) -> 3 | F11: =ROUND(D10*Parameters!$B$16,0) -> 0 | G11: =ROUND(D10*Parameters!$B$17,0) -> 2 | H11: =D11*Parameters!$B$22 -> 300 | I11: =MAX(Parameters!$B$13,H10*Parameters!$B$12) -> 300 | J11: =D11*Parameters!$B$20 -> 160 | K11: =IF(D11<=100,Parameters!$B$6,IF(D11<=500,Parameters!$B$7,IF(D11<=2000,Parameters!$B$8,IF(D11<=10000,Parameters!$B$9,Parameters!$B$10)))) -> 1000 | L11: =I11+J11+K11 -> 1460 | M11: =H11-J11 -> 140 | N11: =H11-L11 -> -1160 | O11: =O10+N11 -> -15118 | P11: =IF(H11<>0,M11/H11,0) -> 0.46666667 | Q11: =IF(H11<>0,N11/H11,0) -> -3.8666667 | R11: =Parameters!$B$22 -> 15 | S11: =Parameters!$B$20 -> 8 | T11: =Parameters!$B$14 -> 90 | U11: =IF(Parameters!$B$17<>0,(Parameters!$B$22-Parameters!$B$20)/Parameters!$B$17,0) -> 77.777778 | V11: =IF((Parameters!$B$22-Parameters!$B$20)>0,Parameters!$B$14/(Parameters!$B$22-Parameters!$B$20),999) -> 12.857143 | W11: =IF(Parameters!$B$14<>0,IF(Parameters!$B$17<>0,(Parameters!$B$22-Parameters!$B$20)/(Parameters!$B$17*Parameters!$B$14),0),0) -> 0.86419753 | X11: =IF(O11>=0,1,0) -> 0
A12: 11 | B12: M11 | C12: Pessimistic | D12: =MAX(0,D11+E12+F12-G12) -> 21 | E12: =ROUND(I12/Parameters!$B$14,0) -> 3 | F12: =ROUND(D11*Parameters!$B$16,0) -> 0 | G12: =ROUND(D11*Parameters!$B$17,0) -> 2 | H12: =D12*Parameters!$B$22 -> 315 | I12: =MAX(Parameters!$B$13,H11*Parameters!$B$12) -> 300 | J12: =D12*Parameters!$B$20 -> 168 | K12: =IF(D12<=100,Parameters!$B$6,IF(D12<=500,Parameters!$B$7,IF(D12<=2000,Parameters!$B$8,IF(D12<=10000,Parameters!$B$9,Parameters!$B$10)))) -> 1000 | L12: =I12+J12+K12 -> 1468 | M12: =H12-J12 -> 147 | N12: =H12-L12 -> -1153 | O12: =O11+N12 -> -16271 | P12: =IF(H12<>0,M12/H12,0) -> 0.46666667 | Q12: =IF(H12<>0,N12/H12,0) -> -3.6603175 | R12: =Parameters!$B$22 -> 15 | S12: =Parameters!$B$20 -> 8 | T12: =Parameters!$B$14 -> 90 | U12: =IF(Parameters!$B$17<>0,(Parameters!$B$22-Parameters!$B$20)/Parameters!$B$17,0) -> 77.777778 | V12: =IF((Parameters!$B$22-Parameters!$B$20)>0,Parameters!$B$14/(Parameters!$B$22-Parameters!$B$20),999) -> 12.857143 | W12: =IF(Parameters!$B$14<>0,IF(Parameters!$B$17<>0,(Parameters!$B$22-Parameters!$B$20)/(Parameters!$B$17*Parameters!$B$14),0),0) -> 0.86419753 | X12: =IF(O12>=0,1,0) -> 0
A13: 12 | B13: M12 | C13: Pessimistic | D13: =MAX(0,D12+E13+F13-G13) -> 22 | E13: =ROUND(I13/Parameters!$B$14,0) -> 3 | F13: =ROUND(D12*Parameters!$B$16,0) -> 0 | G13: =ROUND(D12*Parameters!$B$17,0) -> 2 | H13: =D13*Parameters!$B$22 -> 330 | I13: =MAX(Parameters!$B$13,H12*Parameters!$B$12) -> 300 | J13: =D13*Parameters!$B$20 -> 176 | K13: =IF(D13<=100,Parameters!$B$6,IF(D13<=500,Parameters!$B$7,IF(D13<=2000,Parameters!$B$8,IF(D13<=10000,Parameters!$B$9,Parameters!$B$10)))) -> 1000 | L13: =I13+J13+K13 -> 1476 | M13: =H13-J13 -> 154 | N13: =H13-L13 -> -1146 | O13: =O12+N13 -> -17417 | P13: =IF(H13<>0,M13/H13,0) -> 0.46666667 | Q13: =IF(H13<>0,N13/H13,0) -> -3.4727273 | R13: =Parameters!$B$22 -> 15 | S13: =Parameters!$B$20 -> 8 | T13: =Parameters!$B$14 -> 90 | U13: =IF(Parameters!$B$17<>0,(Parameters!$B$22-Parameters!$B$20)/Parameters!$B$17,0) -> 77.777778 | V13: =IF((Parameters!$B$22-Parameters!$B$20)>0,Parameters!$B$14/(Parameters!$B$22-Parameters!$B$20),999) -> 12.857143 | W13: =IF(Parameters!$B$14<>0,IF(Parameters!$B$17<>0,(Parameters!$B$22-Parameters!$B$20)/(Parameters!$B$17*Parameters!$B$14),0),0) -> 0.86419753 | X13: =IF(O13>=0,1,0) -> 0
A14: 13 | B14: M13 | C14: Pessimistic | D14: =MAX(0,D13+E14+F14-G14) -> 23 | E14: =ROUND(I14/Parameters!$B$14,0) -> 3 | F14: =ROUND(D13*Parameters!$B$16,0) -> 0 | G14: =ROUND(D13*Parameters!$B$17,0) -> 2 | H14: =D14*Parameters!$B$22 -> 345 | I14: =MAX(Parameters!$B$13,H13*Parameters!$B$12) -> 300 | J14: =D14*Parameters!$B$20 -> 184 | K14: =IF(D14<=100,Parameters!$B$6,IF(D14<=500,Parameters!$B$7,IF(D14<=2000,Parameters!$B$8,IF(D14<=10000,Parameters!$B$9,Parameters!$B$10)))) -> 1000 | L14: =I14+J14+K14 -> 1484 | M14: =H14-J14 -> 161 | N14: =H14-L14 -> -1139 | O14: =O13+N14 -> -18556 | P14: =IF(H14<>0,M14/H14,0) -> 0.46666667 | Q14: =IF(H14<>0,N14/H14,0) -> -3.3014493 | R14: =Parameters!$B$22 -> 15 | S14: =Parameters!$B$20 -> 8 | T14: =Parameters!$B$14 -> 90 | U14: =IF(Parameters!$B$17<>0,(Parameters!$B$22-Parameters!$B$20)/Parameters!$B$17,0) -> 77.777778 | V14: =IF((Parameters!$B$22-Parameters!$B$20)>0,Parameters!$B$14/(Parameters!$B$22-Parameters!$B$20),999) -> 12.857143 | W14: =IF(Parameters!$B$14<>0,IF(Parameters!$B$17<>0,(Parameters!$B$22-Parameters!$B$20)/(Parameters!$B$17*Parameters!$B$14),0),0) -> 0.86419753 | X14: =IF(O14>=0,1,0) -> 0
... A37: 36 | B37: M36 | C37: Pessimistic | D37: =MAX(0,D36+E37+F37-G37) -> 28 | E37: =ROUND(I37/Parameters!$B$14,0) -> 3 | F37: =ROUND(D36*Parameters!$B$16,0) -> 0 | G37: =ROUND(D36*Parameters!$B$17,0) -> 3 | H37: =D37*Parameters!$B$22 -> 420 | I37: =MAX(Parameters!$B$13,H36*Parameters!$B$12) -> 300 | J37: =D37*Parameters!$B$20 -> 224 | K37: =IF(D37<=100,Parameters!$B$6,IF(D37<=500,Parameters!$B$7,IF(D37<=2000,Parameters!$B$8,IF(D37<=10000,Parameters!$B$9,Parameters!$B$10)))) -> 1000 | L37: =I37+J37+K37 -> 1524 | M37: =H37-J37 -> 196 | N37: =H37-L37 -> -1104 | O37: =O36+N37 -> -44018 | P37: =IF(H37<>0,M37/H37,0) -> 0.46666667 | Q37: =IF(H37<>0,N37/H37,0) -> -2.6285714 | R37: =Parameters!$B$22 -> 15 | S37: =Parameters!$B$20 -> 8 | T37: =Parameters!$B$14 -> 90 | U37: =IF(Parameters!$B$17<>0,(Parameters!$B$22-Parameters!$B$20)/Parameters!$B$17,0) -> 77.777778 | V37: =IF((Parameters!$B$22-Parameters!$B$20)>0,Parameters!$B$14/(Parameters!$B$22-Parameters!$B$20),999) -> 12.857143 | W37: =IF(Parameters!$B$14<>0,IF(Parameters!$B$17<>0,(Parameters!$B$22-Parameters!$B$20)/(Parameters!$B$17*Parameters!$B$14),0),0) -> 0.86419753 | X37: =IF(O37>=0,1,0) -> 0
A38: 1 | B38: M01 | C38: Base Case | D38: =MAX(0,Parameters!$C$18+E38+F38-G38) -> 10 | E38: =ROUND(I38/Parameters!$C$14,0) -> 10 | F38: =ROUND(Parameters!$C$18*Parameters!$C$16,0) -> 0 | G38: =ROUND(Parameters!$C$18*Parameters!$C$17,0) -> 0 | H38: =D38*Parameters!$C$22 -> 230 | I38: =MAX(Parameters!$C$13,0) -> 600 | J38: =D38*Parameters!$C$20 -> 70 | K38: =IF(D38<=100,Parameters!$B$6,IF(D38<=500,Parameters!$B$7,IF(D38<=2000,Parameters!$B$8,IF(D38<=10000,Parameters!$B$9,Parameters!$B$10)))) -> 1000 | L38: =I38+J38+K38 -> 1670 | M38: =H38-J38 -> 160 | N38: =H38-L38 -> -1440 | O38: =N38-Parameters!$C$4 -> -3440 | P38: =IF(H38<>0,M38/H38,0) -> 0.69565217 | Q38: =IF(H38<>0,N38/H38,0) -> -6.2608696 | R38: =Parameters!$C$22 -> 23 | S38: =Parameters!$C$20 -> 7 | T38: =Parameters!$C$14 -> 60 | U38: =IF(Parameters!$C$17<>0,(Parameters!$C$22-Parameters!$C$20)/Parameters!$C$17,0) -> 266.66667 | V38: =IF((Parameters!$C$22-Parameters!$C$20)>0,Parameters!$C$14/(Parameters!$C$22-Parameters!$C$20),999) -> 3.75 | W38: =IF(Parameters!$C$14<>0,IF(Parameters!$C$17<>0,(Parameters!$C$22-Parameters!$C$20)/(Parameters!$C$17*Parameters!$C$14),0),0) -> 4.4444444 | X38: =IF(O38>=0,1,0) -> 0
A39: 2 | B39: M02 | C39: Base Case | D39: =MAX(0,D38+E39+F39-G39) -> 19 | E39: =ROUND(I39/Parameters!$C$14,0) -> 10 | F39: =ROUND(D38*Parameters!$C$16,0) -> 0 | G39: =ROUND(D38*Parameters!$C$17,0) -> 1 | H39: =D39*Parameters!$C$22 -> 437 | I39: =MAX(Parameters!$C$13,H38*Parameters!$C$12) -> 600 | J39: =D39*Parameters!$C$20 -> 133 | K39: =IF(D39<=100,Parameters!$B$6,IF(D39<=500,Parameters!$B$7,IF(D39<=2000,Parameters!$B$8,IF(D39<=10000,Parameters!$B$9,Parameters!$B$10)))) -> 1000 | L39: =I39+J39+K39 -> 1733 | M39: =H39-J39 -> 304 | N39: =H39-L39 -> -1296 | O39: =O38+N39 -> -4736 | P39: =IF(H39<>0,M39/H39,0) -> 0.69565217 | Q39: =IF(H39<>0,N39/H39,0) -> -2.9656751 | R39: =Parameters!$C$22 -> 23 | S39: =Parameters!$C$20 -> 7 | T39: =Parameters!$C$14 -> 60 | U39: =IF(Parameters!$C$17<>0,(Parameters!$C$22-Parameters!$C$20)/Parameters!$C$17,0) -> 266.66667 | V39: =IF((Parameters!$C$22-Parameters!$C$20)>0,Parameters!$C$14/(Parameters!$C$22-Parameters!$C$20),999) -> 3.75 | W39: =IF(Parameters!$C$14<>0,IF(Parameters!$C$17<>0,(Parameters!$C$22-Parameters!$C$20)/(Parameters!$C$17*Parameters!$C$14),0),0) -> 4.4444444 | X39: =IF(O39>=0,1,0) -> 0
A40: 3 | B40: M03 | C40: Base Case | D40: =MAX(0,D39+E40+F40-G40) -> 29 | E40: =ROUND(I40/Parameters!$C$14,0) -> 10 | F40: =ROUND(D39*Parameters!$C$16,0) -> 1 | G40: =ROUND(D39*Parameters!$C$17,0) -> 1 | H40: =D40*Parameters!$C$22 -> 667 | I40: =MAX(Parameters!$C$13,H39*Parameters!$C$12) -> 600 | J40: =D40*Parameters!$C$20 -> 203 | K40: =IF(D40<=100,Parameters!$B$6,IF(D40<=500,Parameters!$B$7,IF(D40<=2000,Parameters!$B$8,IF(D40<=10000,Parameters!$B$9,Parameters!$B$10)))) -> 1000 | L40: =I40+J40+K40 -> 1803 | M40: =H40-J40 -> 464 | N40: =H40-L40 -> -1136 | O40: =O39+N40 -> -5872 | P40: =IF(H40<>0,M40/H40,0) -> 0.69565217 | Q40: =IF(H40<>0,N40/H40,0) -> -1.7031484 | R40: =Parameters!$C$22 -> 23 | S40: =Parameters!$C$20 -> 7 | T40: =Parameters!$C$14 -> 60 | U40: =IF(Parameters!$C$17<>0,(Parameters!$C$22-Parameters!$C$20)/Parameters!$C$17,0) -> 266.66667 | V40: =IF((Parameters!$C$22-Parameters!$C$20)>0,Parameters!$C$14/(Parameters!$C$22-Parameters!$C$20),999) -> 3.75 | W40: =IF(Parameters!$C$14<>0,IF(Parameters!$C$17<>0,(Parameters!$C$22-Parameters!$C$20)/(Parameters!$C$17*Parameters!$C$14),0),0) -> 4.4444444 | X40: =IF(O40>=0,1,0) -> 0
A41: 4 | B41: M04 | C41: Base Case | D41: =MAX(0,D40+E41+F41-G41) -> 38 | E41: =ROUND(I41/Parameters!$C$14,0) -> 10 | F41: =ROUND(D40*Parameters!$C$16,0) -> 1 | G41: =ROUND(D40*Parameters!$C$17,0) -> 2 | H41: =D41*Parameters!$C$22 -> 874 | I41: =MAX(Parameters!$C$13,H40*Parameters!$C$12) -> 600 | J41: =D41*Parameters!$C$20 -> 266 | K41: =IF(D41<=100,Parameters!$B$6,IF(D41<=500,Parameters!$B$7,IF(D41<=2000,Parameters!$B$8,IF(D41<=10000,Parameters!$B$9,Parameters!$B$10)))) -> 1000 | L41: =I41+J41+K41 -> 1866 | M41: =H41-J41 -> 608 | N41: =H41-L41 -> -992 | O41: =O40+N41 -> -6864 | P41: =IF(H41<>0,M41/H41,0) -> 0.69565217 | Q41: =IF(H41<>0,N41/H41,0) -> -1.1350114 | R41: =Parameters!$C$22 -> 23 | S41: =Parameters!$C$20 -> 7 | T41: =Parameters!$C$14 -> 60 | U41: =IF(Parameters!$C$17<>0,(Parameters!$C$22-Parameters!$C$20)/Parameters!$C$17,0) -> 266.66667 | V41: =IF((Parameters!$C$22-Parameters!$C$20)>0,Parameters!$C$14/(Parameters!$C$22-Parameters!$C$20),999) -> 3.75 | W41: =IF(Parameters!$C$14<>0,IF(Parameters!$C$17<>0,(Parameters!$C$22-Parameters!$C$20)/(Parameters!$C$17*Parameters!$C$14),0),0) -> 4.4444444 | X41: =IF(O41>=0,1,0) -> 0
A42: 5 | B42: M05 | C42: Base Case | D42: =MAX(0,D41+E42+F42-G42) -> 47 | E42: =ROUND(I42/Parameters!$C$14,0) -> 10 | F42: =ROUND(D41*Parameters!$C$16,0) -> 1 | G42: =ROUND(D41*Parameters!$C$17,0) -> 2 | H42: =D42*Parameters!$C$22 -> 1081 | I42: =MAX(Parameters!$C$13,H41*Parameters!$C$12) -> 600 | J42: =D42*Parameters!$C$20 -> 329 | K42: =IF(D42<=100,Parameters!$B$6,IF(D42<=500,Parameters!$B$7,IF(D42<=2000,Parameters!$B$8,IF(D42<=10000,Parameters!$B$9,Parameters!$B$10)))) -> 1000 | L42: =I42+J42+K42 -> 1929 | M42: =H42-J42 -> 752 | N42: =H42-L42 -> -848 | O42: =O41+N42 -> -7712 | P42: =IF(H42<>0,M42/H42,0) -> 0.69565217 | Q42: =IF(H42<>0,N42/H42,0) -> -0.78445883 | R42: =Parameters!$C$22 -> 23 | S42: =Parameters!$C$20 -> 7 | T42: =Parameters!$C$14 -> 60 | U42: =IF(Parameters!$C$17<>0,(Parameters!$C$22-Parameters!$C$20)/Parameters!$C$17,0) -> 266.66667 | V42: =IF((Parameters!$C$22-Parameters!$C$20)>0,Parameters!$C$14/(Parameters!$C$22-Parameters!$C$20),999) -> 3.75 | W42: =IF(Parameters!$C$14<>0,IF(Parameters!$C$17<>0,(Parameters!$C$22-Parameters!$C$20)/(Parameters!$C$17*Parameters!$C$14),0),0) -> 4.4444444 | X42: =IF(O42>=0,1,0) -> 0
A43: 6 | B43: M06 | C43: Base Case | D43: =MAX(0,D42+E43+F43-G43) -> 55 | E43: =ROUND(I43/Parameters!$C$14,0) -> 10 | F43: =ROUND(D42*Parameters!$C$16,0) -> 1 | G43: =ROUND(D42*Parameters!$C$17,0) -> 3 | H43: =D43*Parameters!$C$22 -> 1265 | I43: =MAX(Parameters!$C$13,H42*Parameters!$C$12) -> 600 | J43: =D43*Parameters!$C$20 -> 385 | K43: =IF(D43<=100,Parameters!$B$6,IF(D43<=500,Parameters!$B$7,IF(D43<=2000,Parameters!$B$8,IF(D43<=10000,Parameters!$B$9,Parameters!$B$10)))) -> 1000 | L43: =I43+J43+K43 -> 1985 | M43: =H43-J43 -> 880 | N43: =H43-L43 -> -720 | O43: =O42+N43 -> -8432 | P43: =IF(H43<>0,M43/H43,0) -> 0.69565217 | Q43: =IF(H43<>0,N43/H43,0) -> -0.56916996 | R43: =Parameters!$C$22 -> 23 | S43: =Parameters!$C$20 -> 7 | T43: =Parameters!$C$14 -> 60 | U43: =IF(Parameters!$C$17<>0,(Parameters!$C$22-Parameters!$C$20)/Parameters!$C$17,0) -> 266.66667 | V43: =IF((Parameters!$C$22-Parameters!$C$20)>0,Parameters!$C$14/(Parameters!$C$22-Parameters!$C$20),999) -> 3.75 | W43: =IF(Parameters!$C$14<>0,IF(Parameters!$C$17<>0,(Parameters!$C$22-Parameters!$C$20)/(Parameters!$C$17*Parameters!$C$14),0),0) -> 4.4444444 | X43: =IF(O43>=0,1,0) -> 0
A44: 7 | B44: M07 | C44: Base Case | D44: =MAX(0,D43+E44+F44-G44) -> 64 | E44: =ROUND(I44/Parameters!$C$14,0) -> 10 | F44: =ROUND(D43*Parameters!$C$16,0) -> 2 | G44: =ROUND(D43*Parameters!$C$17,0) -> 3 | H44: =D44*Parameters!$C$22 -> 1472 | I44: =MAX(Parameters!$C$13,H43*Parameters!$C$12) -> 600 | J44: =D44*Parameters!$C$20 -> 448 | K44: =IF(D44<=100,Parameters!$B$6,IF(D44<=500,Parameters!$B$7,IF(D44<=2000,Parameters!$B$8,IF(D44<=10000,Parameters!$B$9,Parameters!$B$10)))) -> 1000 | L44: =I44+J44+K44 -> 2048 | M44: =H44-J44 -> 1024 | N44: =H44-L44 -> -576 | O44: =O43+N44 -> -9008 | P44: =IF(H44<>0,M44/H44,0) -> 0.69565217 | Q44: =IF(H44<>0,N44/H44,0) -> -0.39130435 | R44: =Parameters!$C$22 -> 23 | S44: =Parameters!$C$20 -> 7 | T44: =Parameters!$C$14 -> 60 | U44: =IF(Parameters!$C$17<>0,(Parameters!$C$22-Parameters!$C$20)/Parameters!$C$17,0) -> 266.66667 | V44: =IF((Parameters!$C$22-Parameters!$C$20)>0,Parameters!$C$14/(Parameters!$C$22-Parameters!$C$20),999) -> 3.75 | W44: =IF(Parameters!$C$14<>0,IF(Parameters!$C$17<>0,(Parameters!$C$22-Parameters!$C$20)/(Parameters!$C$17*Parameters!$C$14),0),0) -> 4.4444444 | X44: =IF(O44>=0,1,0) -> 0
A45: 8 | B45: M08 | C45: Base Case | D45: =MAX(0,D44+E45+F45-G45) -> 72 | E45: =ROUND(I45/Parameters!$C$14,0) -> 10 | F45: =ROUND(D44*Parameters!$C$16,0) -> 2 | G45: =ROUND(D44*Parameters!$C$17,0) -> 4 | H45: =D45*Parameters!$C$22 -> 1656 | I45: =MAX(Parameters!$C$13,H44*Parameters!$C$12) -> 600 | J45: =D45*Parameters!$C$20 -> 504 | K45: =IF(D45<=100,Parameters!$B$6,IF(D45<=500,Parameters!$B$7,IF(D45<=2000,Parameters!$B$8,IF(D45<=10000,Parameters!$B$9,Parameters!$B$10)))) -> 1000 | L45: =I45+J45+K45 -> 2104 | M45: =H45-J45 -> 1152 | N45: =H45-L45 -> -448 | O45: =O44+N45 -> -9456 | P45: =IF(H45<>0,M45/H45,0) -> 0.69565217 | Q45: =IF(H45<>0,N45/H45,0) -> -0.2705314 | R45: =Parameters!$C$22 -> 23 | S45: =Parameters!$C$20 -> 7 | T45: =Parameters!$C$14 -> 60 | U45: =IF(Parameters!$C$17<>0,(Parameters!$C$22-Parameters!$C$20)/Parameters!$C$17,0) -> 266.66667 | V45: =IF((Parameters!$C$22-Parameters!$C$20)>0,Parameters!$C$14/(Parameters!$C$22-Parameters!$C$20),999) -> 3.75 | W45: =IF(Parameters!$C$14<>0,IF(Parameters!$C$17<>0,(Parameters!$C$22-Parameters!$C$20)/(Parameters!$C$17*Parameters!$C$14),0),0) -> 4.4444444 | X45: =IF(O45>=0,1,0) -> 0
A46: 9 | B46: M09 | C46: Base Case | D46: =MAX(0,D45+E46+F46-G46) -> 80 | E46: =ROUND(I46/Parameters!$C$14,0) -> 10 | F46: =ROUND(D45*Parameters!$C$16,0) -> 2 | G46: =ROUND(D45*Parameters!$C$17,0) -> 4 | H46: =D46*Parameters!$C$22 -> 1840 | I46: =MAX(Parameters!$C$13,H45*Parameters!$C$12) -> 600 | J46: =D46*Parameters!$C$20 -> 560 | K46: =IF(D46<=100,Parameters!$B$6,IF(D46<=500,Parameters!$B$7,IF(D46<=2000,Parameters!$B$8,IF(D46<=10000,Parameters!$B$9,Parameters!$B$10)))) -> 1000 | L46: =I46+J46+K46 -> 2160 | M46: =H46-J46 -> 1280 | N46: =H46-L46 -> -320 | O46: =O45+N46 -> -9776 | P46: =IF(H46<>0,M46/H46,0) -> 0.69565217 | Q46: =IF(H46<>0,N46/H46,0) -> -0.17391304 | R46: =Parameters!$C$22 -> 23 | S46: =Parameters!$C$20 -> 7 | T46: =Parameters!$C$14 -> 60 | U46: =IF(Parameters!$C$17<>0,(Parameters!$C$22-Parameters!$C$20)/Parameters!$C$17,0) -> 266.66667 | V46: =IF((Parameters!$C$22-Parameters!$C$20)>0,Parameters!$C$14/(Parameters!$C$22-Parameters!$C$20),999) -> 3.75 | W46: =IF(Parameters!$C$14<>0,IF(Parameters!$C$17<>0,(Parameters!$C$22-Parameters!$C$20)/(Parameters!$C$17*Parameters!$C$14),0),0) -> 4.4444444 | X46: =IF(O46>=0,1,0) -> 0
A47: 10 | B47: M10 | C47: Base Case | D47: =MAX(0,D46+E47+F47-G47) -> 88 | E47: =ROUND(I47/Parameters!$C$14,0) -> 11 | F47: =ROUND(D46*Parameters!$C$16,0) -> 2 | G47: =ROUND(D46*Parameters!$C$17,0) -> 5 | H47: =D47*Parameters!$C$22 -> 2024 | I47: =MAX(Parameters!$C$13,H46*Parameters!$C$12) -> 644 | J47: =D47*Parameters!$C$20 -> 616 | K47: =IF(D47<=100,Parameters!$B$6,IF(D47<=500,Parameters!$B$7,IF(D47<=2000,Parameters!$B$8,IF(D47<=10000,Parameters!$B$9,Parameters!$B$10)))) -> 1000 | L47: =I47+J47+K47 -> 2260 | M47: =H47-J47 -> 1408 | N47: =H47-L47 -> -236 | O47: =O46+N47 -> -10012 | P47: =IF(H47<>0,M47/H47,0) -> 0.69565217 | Q47: =IF(H47<>0,N47/H47,0) -> -0.11660079 | R47: =Parameters!$C$22 -> 23 | S47: =Parameters!$C$20 -> 7 | T47: =Parameters!$C$14 -> 60 | U47: =IF(Parameters!$C$17<>0,(Parameters!$C$22-Parameters!$C$20)/Parameters!$C$17,0) -> 266.66667 | V47: =IF((Parameters!$C$22-Parameters!$C$20)>0,Parameters!$C$14/(Parameters!$C$22-Parameters!$C$20),999) -> 3.75 | W47: =IF(Parameters!$C$14<>0,IF(Parameters!$C$17<>0,(Parameters!$C$22-Parameters!$C$20)/(Parameters!$C$17*Parameters!$C$14),0),0) -> 4.4444444 | X47: =IF(O47>=0,1,0) -> 0
A48: 11 | B48: M11 | C48: Base Case | D48: =MAX(0,D47+E48+F48-G48) -> 98 | E48: =ROUND(I48/Parameters!$C$14,0) -> 12 | F48: =ROUND(D47*Parameters!$C$16,0) -> 3 | G48: =ROUND(D47*Parameters!$C$17,0) -> 5 | H48: =D48*Parameters!$C$22 -> 2254 | I48: =MAX(Parameters!$C$13,H47*Parameters!$C$12) -> 708.4 | J48: =D48*Parameters!$C$20 -> 686 | K48: =IF(D48<=100,Parameters!$B$6,IF(D48<=500,Parameters!$B$7,IF(D48<=2000,Parameters!$B$8,IF(D48<=10000,Parameters!$B$9,Parameters!$B$10)))) -> 1000 | L48: =I48+J48+K48 -> 2394.4 | M48: =H48-J48 -> 1568 | N48: =H48-L48 -> -140.4 | O48: =O47+N48 -> -10152.4 | P48: =IF(H48<>0,M48/H48,0) -> 0.69565217 | Q48: =IF(H48<>0,N48/H48,0) -> -0.062289264 | R48: =Parameters!$C$22 -> 23 | S48: =Parameters!$C$20 -> 7 | T48: =Parameters!$C$14 -> 60 | U48: =IF(Parameters!$C$17<>0,(Parameters!$C$22-Parameters!$C$20)/Parameters!$C$17,0) -> 266.66667 | V48: =IF((Parameters!$C$22-Parameters!$C$20)>0,Parameters!$C$14/(Parameters!$C$22-Parameters!$C$20),999) -> 3.75 | W48: =IF(Parameters!$C$14<>0,IF(Parameters!$C$17<>0,(Parameters!$C$22-Parameters!$C$20)/(Parameters!$C$17*Parameters!$C$14),0),0) -> 4.4444444 | X48: =IF(O48>=0,1,0) -> 0
A49: 12 | B49: M12 | C49: Base Case | D49: =MAX(0,D48+E49+F49-G49) -> 108 | E49: =ROUND(I49/Parameters!$C$14,0) -> 13 | F49: =ROUND(D48*Parameters!$C$16,0) -> 3 | G49: =ROUND(D48*Parameters!$C$17,0) -> 6 | H49: =D49*Parameters!$C$22 -> 2484 | I49: =MAX(Parameters!$C$13,H48*Parameters!$C$12) -> 788.9 | J49: =D49*Parameters!$C$20 -> 756 | K49: =IF(D49<=100,Parameters!$B$6,IF(D49<=500,Parameters!$B$7,IF(D49<=2000,Parameters!$B$8,IF(D49<=10000,Parameters!$B$9,Parameters!$B$10)))) -> 2000 | L49: =I49+J49+K49 -> 3544.9 | M49: =H49-J49 -> 1728 | N49: =H49-L49 -> -1060.9 | O49: =O48+N49 -> -11213.3 | P49: =IF(H49<>0,M49/H49,0) -> 0.69565217 | Q49: =IF(H49<>0,N49/H49,0) -> -0.4270934 | R49: =Parameters!$C$22 -> 23 | S49: =Parameters!$C$20 -> 7 | T49: =Parameters!$C$14 -> 60 | U49: =IF(Parameters!$C$17<>0,(Parameters!$C$22-Parameters!$C$20)/Parameters!$C$17,0) -> 266.66667 | V49: =IF((Parameters!$C$22-Parameters!$C$20)>0,Parameters!$C$14/(Parameters!$C$22-Parameters!$C$20),999) -> 3.75 | W49: =IF(Parameters!$C$14<>0,IF(Parameters!$C$17<>0,(Parameters!$C$22-Parameters!$C$20)/(Parameters!$C$17*Parameters!$C$14),0),0) -> 4.4444444 | X49: =IF(O49>=0,1,0) -> 0
A50: 13 | B50: M13 | C50: Base Case | D50: =MAX(0,D49+E50+F50-G50) -> 119 | E50: =ROUND(I50/Parameters!$C$14,0) -> 14 | F50: =ROUND(D49*Parameters!$C$16,0) -> 3 | G50: =ROUND(D49*Parameters!$C$17,0) -> 6 | H50: =D50*Parameters!$C$22 -> 2737 | I50: =MAX(Parameters!$C$13,H49*Parameters!$C$12) -> 869.4 | J50: =D50*Parameters!$C$20 -> 833 | K50: =IF(D50<=100,Parameters!$B$6,IF(D50<=500,Parameters!$B$7,IF(D50<=2000,Parameters!$B$8,IF(D50<=10000,Parameters!$B$9,Parameters!$B$10)))) -> 2000 | L50: =I50+J50+K50 -> 3702.4 | M50: =H50-J50 -> 1904 | N50: =H50-L50 -> -965.4 | O50: =O49+N50 -> -12178.7 | P50: =IF(H50<>0,M50/H50,0) -> 0.69565217 | Q50: =IF(H50<>0,N50/H50,0) -> -0.35272196 | R50: =Parameters!$C$22 -> 23 | S50: =Parameters!$C$20 -> 7 | T50: =Parameters!$C$14 -> 60 | U50: =IF(Parameters!$C$17<>0,(Parameters!$C$22-Parameters!$C$20)/Parameters!$C$17,0) -> 266.66667 | V50: =IF((Parameters!$C$22-Parameters!$C$20)>0,Parameters!$C$14/(Parameters!$C$22-Parameters!$C$20),999) -> 3.75 | W50: =IF(Parameters!$C$14<>0,IF(Parameters!$C$17<>0,(Parameters!$C$22-Parameters!$C$20)/(Parameters!$C$17*Parameters!$C$14),0),0) -> 4.4444444 | X50: =IF(O50>=0,1,0) -> 0
... A73: 36 | B73: M36 | C73: Base Case | D73: =MAX(0,D72+E73+F73-G73) -> 1163 | E73: =ROUND(I73/Parameters!$C$14,0) -> 141 | F73: =ROUND(D72*Parameters!$C$16,0) -> 32 | G73: =ROUND(D72*Parameters!$C$17,0) -> 63 | H73: =D73*Parameters!$C$22 -> 26749 | I73: =MAX(Parameters!$C$13,H72*Parameters!$C$12) -> 8476.65 | J73: =D73*Parameters!$C$20 -> 8141 | K73: =IF(D73<=100,Parameters!$B$6,IF(D73<=500,Parameters!$B$7,IF(D73<=2000,Parameters!$B$8,IF(D73<=10000,Parameters!$B$9,Parameters!$B$10)))) -> 4000 | L73: =I73+J73+K73 -> 20617.65 | M73: =H73-J73 -> 18608 | N73: =H73-L73 -> 6131.35 | O73: =O72+N73 -> 20303.55 | P73: =IF(H73<>0,M73/H73,0) -> 0.69565217 | Q73: =IF(H73<>0,N73/H73,0) -> 0.22921791 | R73: =Parameters!$C$22 -> 23 | S73: =Parameters!$C$20 -> 7 | T73: =Parameters!$C$14 -> 60 | U73: =IF(Parameters!$C$17<>0,(Parameters!$C$22-Parameters!$C$20)/Parameters!$C$17,0) -> 266.66667 | V73: =IF((Parameters!$C$22-Parameters!$C$20)>0,Parameters!$C$14/(Parameters!$C$22-Parameters!$C$20),999) -> 3.75 | W73: =IF(Parameters!$C$14<>0,IF(Parameters!$C$17<>0,(Parameters!$C$22-Parameters!$C$20)/(Parameters!$C$17*Parameters!$C$14),0),0) -> 4.4444444 | X73: =IF(O73>=0,1,0) -> 1
A74: 1 | B74: M01 | C74: Optimistic | D74: =MAX(0,Parameters!$D$18+E74+F74-G74) -> 15 | E74: =ROUND(I74/Parameters!$D$14,0) -> 15 | F74: =ROUND(Parameters!$D$18*Parameters!$D$16,0) -> 0 | G74: =ROUND(Parameters!$D$18*Parameters!$D$17,0) -> 0 | H74: =D74*Parameters!$D$22 -> 435 | I74: =MAX(Parameters!$D$13,0) -> 800 | J74: =D74*Parameters!$D$20 -> 90 | K74: =IF(D74<=100,Parameters!$B$6,IF(D74<=500,Parameters!$B$7,IF(D74<=2000,Parameters!$B$8,IF(D74<=10000,Parameters!$B$9,Parameters!$B$10)))) -> 1000 | L74: =I74+J74+K74 -> 1890 | M74: =H74-J74 -> 345 | N74: =H74-L74 -> -1455 | O74: =N74-Parameters!$D$4 -> -2455 | P74: =IF(H74<>0,M74/H74,0) -> 0.79310345 | Q74: =IF(H74<>0,N74/H74,0) -> -3.3448276 | R74: =Parameters!$D$22 -> 29 | S74: =Parameters!$D$20 -> 6 | T74: =Parameters!$D$14 -> 55 | U74: =IF(Parameters!$D$17<>0,(Parameters!$D$22-Parameters!$D$20)/Parameters!$D$17,0) -> 575 | V74: =IF((Parameters!$D$22-Parameters!$D$20)>0,Parameters!$D$14/(Parameters!$D$22-Parameters!$D$20),999) -> 2.3913043 | W74: =IF(Parameters!$D$14<>0,IF(Parameters!$D$17<>0,(Parameters!$D$22-Parameters!$D$20)/(Parameters!$D$17*Parameters!$D$14),0),0) -> 10.454545 | X74: =IF(O74>=0,1,0) -> 0
A75: 2 | B75: M02 | C75: Optimistic | D75: =MAX(0,D74+E75+F75-G75) -> 30 | E75: =ROUND(I75/Parameters!$D$14,0) -> 15 | F75: =ROUND(D74*Parameters!$D$16,0) -> 1 | G75: =ROUND(D74*Parameters!$D$17,0) -> 1 | H75: =D75*Parameters!$D$22 -> 870 | I75: =MAX(Parameters!$D$13,H74*Parameters!$D$12) -> 800 | J75: =D75*Parameters!$D$20 -> 180 | K75: =IF(D75<=100,Parameters!$B$6,IF(D75<=500,Parameters!$B$7,IF(D75<=2000,Parameters!$B$8,IF(D75<=10000,Parameters!$B$9,Parameters!$B$10)))) -> 1000 | L75: =I75+J75+K75 -> 1980 | M75: =H75-J75 -> 690 | N75: =H75-L75 -> -1110 | O75: =O74+N75 -> -3565 | P75: =IF(H75<>0,M75/H75,0) -> 0.79310345 | Q75: =IF(H75<>0,N75/H75,0) -> -1.2758621 | R75: =Parameters!$D$22 -> 29 | S75: =Parameters!$D$20 -> 6 | T75: =Parameters!$D$14 -> 55 | U75: =IF(Parameters!$D$17<>0,(Parameters!$D$22-Parameters!$D$20)/Parameters!$D$17,0) -> 575 | V75: =IF((Parameters!$D$22-Parameters!$D$20)>0,Parameters!$D$14/(Parameters!$D$22-Parameters!$D$20),999) -> 2.3913043 | W75: =IF(Parameters!$D$14<>0,IF(Parameters!$D$17<>0,(Parameters!$D$22-Parameters!$D$20)/(Parameters!$D$17*Parameters!$D$14),0),0) -> 10.454545 | X75: =IF(O75>=0,1,0) -> 0
A76: 3 | B76: M03 | C76: Optimistic | D76: =MAX(0,D75+E76+F76-G76) -> 45 | E76: =ROUND(I76/Parameters!$D$14,0) -> 15 | F76: =ROUND(D75*Parameters!$D$16,0) -> 1 | G76: =ROUND(D75*Parameters!$D$17,0) -> 1 | H76: =D76*Parameters!$D$22 -> 1305 | I76: =MAX(Parameters!$D$13,H75*Parameters!$D$12) -> 800 | J76: =D76*Parameters!$D$20 -> 270 | K76: =IF(D76<=100,Parameters!$B$6,IF(D76<=500,Parameters!$B$7,IF(D76<=2000,Parameters!$B$8,IF(D76<=10000,Parameters!$B$9,Parameters!$B$10)))) -> 1000 | L76: =I76+J76+K76 -> 2070 | M76: =H76-J76 -> 1035 | N76: =H76-L76 -> -765 | O76: =O75+N76 -> -4330 | P76: =IF(H76<>0,M76/H76,0) -> 0.79310345 | Q76: =IF(H76<>0,N76/H76,0) -> -0.5862069 | R76: =Parameters!$D$22 -> 29 | S76: =Parameters!$D$20 -> 6 | T76: =Parameters!$D$14 -> 55 | U76: =IF(Parameters!$D$17<>0,(Parameters!$D$22-Parameters!$D$20)/Parameters!$D$17,0) -> 575 | V76: =IF((Parameters!$D$22-Parameters!$D$20)>0,Parameters!$D$14/(Parameters!$D$22-Parameters!$D$20),999) -> 2.3913043 | W76: =IF(Parameters!$D$14<>0,IF(Parameters!$D$17<>0,(Parameters!$D$22-Parameters!$D$20)/(Parameters!$D$17*Parameters!$D$14),0),0) -> 10.454545 | X76: =IF(O76>=0,1,0) -> 0
A77: 4 | B77: M04 | C77: Optimistic | D77: =MAX(0,D76+E77+F77-G77) -> 60 | E77: =ROUND(I77/Parameters!$D$14,0) -> 15 | F77: =ROUND(D76*Parameters!$D$16,0) -> 2 | G77: =ROUND(D76*Parameters!$D$17,0) -> 2 | H77: =D77*Parameters!$D$22 -> 1740 | I77: =MAX(Parameters!$D$13,H76*Parameters!$D$12) -> 800 | J77: =D77*Parameters!$D$20 -> 360 | K77: =IF(D77<=100,Parameters!$B$6,IF(D77<=500,Parameters!$B$7,IF(D77<=2000,Parameters!$B$8,IF(D77<=10000,Parameters!$B$9,Parameters!$B$10)))) -> 1000 | L77: =I77+J77+K77 -> 2160 | M77: =H77-J77 -> 1380 | N77: =H77-L77 -> -420 | O77: =O76+N77 -> -4750 | P77: =IF(H77<>0,M77/H77,0) -> 0.79310345 | Q77: =IF(H77<>0,N77/H77,0) -> -0.24137931 | R77: =Parameters!$D$22 -> 29 | S77: =Parameters!$D$20 -> 6 | T77: =Parameters!$D$14 -> 55 | U77: =IF(Parameters!$D$17<>0,(Parameters!$D$22-Parameters!$D$20)/Parameters!$D$17,0) -> 575 | V77: =IF((Parameters!$D$22-Parameters!$D$20)>0,Parameters!$D$14/(Parameters!$D$22-Parameters!$D$20),999) -> 2.3913043 | W77: =IF(Parameters!$D$14<>0,IF(Parameters!$D$17<>0,(Parameters!$D$22-Parameters!$D$20)/(Parameters!$D$17*Parameters!$D$14),0),0) -> 10.454545 | X77: =IF(O77>=0,1,0) -> 0
A78: 5 | B78: M05 | C78: Optimistic | D78: =MAX(0,D77+E78+F78-G78) -> 75 | E78: =ROUND(I78/Parameters!$D$14,0) -> 15 | F78: =ROUND(D77*Parameters!$D$16,0) -> 2 | G78: =ROUND(D77*Parameters!$D$17,0) -> 2 | H78: =D78*Parameters!$D$22 -> 2175 | I78: =MAX(Parameters!$D$13,H77*Parameters!$D$12) -> 800 | J78: =D78*Parameters!$D$20 -> 450 | K78: =IF(D78<=100,Parameters!$B$6,IF(D78<=500,Parameters!$B$7,IF(D78<=2000,Parameters!$B$8,IF(D78<=10000,Parameters!$B$9,Parameters!$B$10)))) -> 1000 | L78: =I78+J78+K78 -> 2250 | M78: =H78-J78 -> 1725 | N78: =H78-L78 -> -75 | O78: =O77+N78 -> -4825 | P78: =IF(H78<>0,M78/H78,0) -> 0.79310345 | Q78: =IF(H78<>0,N78/H78,0) -> -0.034482759 | R78: =Parameters!$D$22 -> 29 | S78: =Parameters!$D$20 -> 6 | T78: =Parameters!$D$14 -> 55 | U78: =IF(Parameters!$D$17<>0,(Parameters!$D$22-Parameters!$D$20)/Parameters!$D$17,0) -> 575 | V78: =IF((Parameters!$D$22-Parameters!$D$20)>0,Parameters!$D$14/(Parameters!$D$22-Parameters!$D$20),999) -> 2.3913043 | W78: =IF(Parameters!$D$14<>0,IF(Parameters!$D$17<>0,(Parameters!$D$22-Parameters!$D$20)/(Parameters!$D$17*Parameters!$D$14),0),0) -> 10.454545 | X78: =IF(O78>=0,1,0) -> 0
A79: 6 | B79: M06 | C79: Optimistic | D79: =MAX(0,D78+E79+F79-G79) -> 93 | E79: =ROUND(I79/Parameters!$D$14,0) -> 18 | F79: =ROUND(D78*Parameters!$D$16,0) -> 3 | G79: =ROUND(D78*Parameters!$D$17,0) -> 3 | H79: =D79*Parameters!$D$22 -> 2697 | I79: =MAX(Parameters!$D$13,H78*Parameters!$D$12) -> 978.75 | J79: =D79*Parameters!$D$20 -> 558 | K79: =IF(D79<=100,Parameters!$B$6,IF(D79<=500,Parameters!$B$7,IF(D79<=2000,Parameters!$B$8,IF(D79<=10000,Parameters!$B$9,Parameters!$B$10)))) -> 1000 | L79: =I79+J79+K79 -> 2536.75 | M79: =H79-J79 -> 2139 | N79: =H79-L79 -> 160.25 | O79: =O78+N79 -> -4664.75 | P79: =IF(H79<>0,M79/H79,0) -> 0.79310345 | Q79: =IF(H79<>0,N79/H79,0) -> 0.059417872 | R79: =Parameters!$D$22 -> 29 | S79: =Parameters!$D$20 -> 6 | T79: =Parameters!$D$14 -> 55 | U79: =IF(Parameters!$D$17<>0,(Parameters!$D$22-Parameters!$D$20)/Parameters!$D$17,0) -> 575 | V79: =IF((Parameters!$D$22-Parameters!$D$20)>0,Parameters!$D$14/(Parameters!$D$22-Parameters!$D$20),999) -> 2.3913043 | W79: =IF(Parameters!$D$14<>0,IF(Parameters!$D$17<>0,(Parameters!$D$22-Parameters!$D$20)/(Parameters!$D$17*Parameters!$D$14),0),0) -> 10.454545 | X79: =IF(O79>=0,1,0) -> 0
A80: 7 | B80: M07 | C80: Optimistic | D80: =MAX(0,D79+E80+F80-G80) -> 115 | E80: =ROUND(I80/Parameters!$D$14,0) -> 22 | F80: =ROUND(D79*Parameters!$D$16,0) -> 4 | G80: =ROUND(D79*Parameters!$D$17,0) -> 4 | H80: =D80*Parameters!$D$22 -> 3335 | I80: =MAX(Parameters!$D$13,H79*Parameters!$D$12) -> 1213.65 | J80: =D80*Parameters!$D$20 -> 690 | K80: =IF(D80<=100,Parameters!$B$6,IF(D80<=500,Parameters!$B$7,IF(D80<=2000,Parameters!$B$8,IF(D80<=10000,Parameters!$B$9,Parameters!$B$10)))) -> 2000 | L80: =I80+J80+K80 -> 3903.65 | M80: =H80-J80 -> 2645 | N80: =H80-L80 -> -568.65 | O80: =O79+N80 -> -5233.4 | P80: =IF(H80<>0,M80/H80,0) -> 0.79310345 | Q80: =IF(H80<>0,N80/H80,0) -> -0.17050975 | R80: =Parameters!$D$22 -> 29 | S80: =Parameters!$D$20 -> 6 | T80: =Parameters!$D$14 -> 55 | U80: =IF(Parameters!$D$17<>0,(Parameters!$D$22-Parameters!$D$20)/Parameters!$D$17,0) -> 575 | V80: =IF((Parameters!$D$22-Parameters!$D$20)>0,Parameters!$D$14/(Parameters!$D$22-Parameters!$D$20),999) -> 2.3913043 | W80: =IF(Parameters!$D$14<>0,IF(Parameters!$D$17<>0,(Parameters!$D$22-Parameters!$D$20)/(Parameters!$D$17*Parameters!$D$14),0),0) -> 10.454545 | X80: =IF(O80>=0,1,0) -> 0
A81: 8 | B81: M08 | C81: Optimistic | D81: =MAX(0,D80+E81+F81-G81) -> 142 | E81: =ROUND(I81/Parameters!$D$14,0) -> 27 | F81: =ROUND(D80*Parameters!$D$16,0) -> 5 | G81: =ROUND(D80*Parameters!$D$17,0) -> 5 | H81: =D81*Parameters!$D$22 -> 4118 | I81: =MAX(Parameters!$D$13,H80*Parameters!$D$12) -> 1500.75 | J81: =D81*Parameters!$D$20 -> 852 | K81: =IF(D81<=100,Parameters!$B$6,IF(D81<=500,Parameters!$B$7,IF(D81<=2000,Parameters!$B$8,IF(D81<=10000,Parameters!$B$9,Parameters!$B$10)))) -> 2000 | L81: =I81+J81+K81 -> 4352.75 | M81: =H81-J81 -> 3266 | N81: =H81-L81 -> -234.75 | O81: =O80+N81 -> -5468.15 | P81: =IF(H81<>0,M81/H81,0) -> 0.79310345 | Q81: =IF(H81<>0,N81/H81,0) -> -0.057005828 | R81: =Parameters!$D$22 -> 29 | S81: =Parameters!$D$20 -> 6 | T81: =Parameters!$D$14 -> 55 | U81: =IF(Parameters!$D$17<>0,(Parameters!$D$22-Parameters!$D$20)/Parameters!$D$17,0) -> 575 | V81: =IF((Parameters!$D$22-Parameters!$D$20)>0,Parameters!$D$14/(Parameters!$D$22-Parameters!$D$20),999) -> 2.3913043 | W81: =IF(Parameters!$D$14<>0,IF(Parameters!$D$17<>0,(Parameters!$D$22-Parameters!$D$20)/(Parameters!$D$17*Parameters!$D$14),0),0) -> 10.454545 | X81: =IF(O81>=0,1,0) -> 0
A82: 9 | B82: M09 | C82: Optimistic | D82: =MAX(0,D81+E82+F82-G82) -> 176 | E82: =ROUND(I82/Parameters!$D$14,0) -> 34 | F82: =ROUND(D81*Parameters!$D$16,0) -> 6 | G82: =ROUND(D81*Parameters!$D$17,0) -> 6 | H82: =D82*Parameters!$D$22 -> 5104 | I82: =MAX(Parameters!$D$13,H81*Parameters!$D$12) -> 1853.1 | J82: =D82*Parameters!$D$20 -> 1056 | K82: =IF(D82<=100,Parameters!$B$6,IF(D82<=500,Parameters!$B$7,IF(D82<=2000,Parameters!$B$8,IF(D82<=10000,Parameters!$B$9,Parameters!$B$10)))) -> 2000 | L82: =I82+J82+K82 -> 4909.1 | M82: =H82-J82 -> 4048 | N82: =H82-L82 -> 194.9 | O82: =O81+N82 -> -5273.25 | P82: =IF(H82<>0,M82/H82,0) -> 0.79310345 | Q82: =IF(H82<>0,N82/H82,0) -> 0.038185737 | R82: =Parameters!$D$22 -> 29 | S82: =Parameters!$D$20 -> 6 | T82: =Parameters!$D$14 -> 55 | U82: =IF(Parameters!$D$17<>0,(Parameters!$D$22-Parameters!$D$20)/Parameters!$D$17,0) -> 575 | V82: =IF((Parameters!$D$22-Parameters!$D$20)>0,Parameters!$D$14/(Parameters!$D$22-Parameters!$D$20),999) -> 2.3913043 | W82: =IF(Parameters!$D$14<>0,IF(Parameters!$D$17<>0,(Parameters!$D$22-Parameters!$D$20)/(Parameters!$D$17*Parameters!$D$14),0),0) -> 10.454545 | X82: =IF(O82>=0,1,0) -> 0
A83: 10 | B83: M10 | C83: Optimistic | D83: =MAX(0,D82+E83+F83-G83) -> 218 | E83: =ROUND(I83/Parameters!$D$14,0) -> 42 | F83: =ROUND(D82*Parameters!$D$16,0) -> 7 | G83: =ROUND(D82*Parameters!$D$17,0) -> 7 | H83: =D83*Parameters!$D$22 -> 6322 | I83: =MAX(Parameters!$D$13,H82*Parameters!$D$12) -> 2296.8 | J83: =D83*Parameters!$D$20 -> 1308 | K83: =IF(D83<=100,Parameters!$B$6,IF(D83<=500,Parameters!$B$7,IF(D83<=2000,Parameters!$B$8,IF(D83<=10000,Parameters!$B$9,Parameters!$B$10)))) -> 2000 | L83: =I83+J83+K83 -> 5604.8 | M83: =H83-J83 -> 5014 | N83: =H83-L83 -> 717.2 | O83: =O82+N83 -> -4556.05 | P83: =IF(H83<>0,M83/H83,0) -> 0.79310345 | Q83: =IF(H83<>0,N83/H83,0) -> 0.11344511 | R83: =Parameters!$D$22 -> 29 | S83: =Parameters!$D$20 -> 6 | T83: =Parameters!$D$14 -> 55 | U83: =IF(Parameters!$D$17<>0,(Parameters!$D$22-Parameters!$D$20)/Parameters!$D$17,0) -> 575 | V83: =IF((Parameters!$D$22-Parameters!$D$20)>0,Parameters!$D$14/(Parameters!$D$22-Parameters!$D$20),999) -> 2.3913043 | W83: =IF(Parameters!$D$14<>0,IF(Parameters!$D$17<>0,(Parameters!$D$22-Parameters!$D$20)/(Parameters!$D$17*Parameters!$D$14),0),0) -> 10.454545 | X83: =IF(O83>=0,1,0) -> 0
A84: 11 | B84: M11 | C84: Optimistic | D84: =MAX(0,D83+E84+F84-G84) -> 270 | E84: =ROUND(I84/Parameters!$D$14,0) -> 52 | F84: =ROUND(D83*Parameters!$D$16,0) -> 9 | G84: =ROUND(D83*Parameters!$D$17,0) -> 9 | H84: =D84*Parameters!$D$22 -> 7830 | I84: =MAX(Parameters!$D$13,H83*Parameters!$D$12) -> 2844.9 | J84: =D84*Parameters!$D$20 -> 1620 | K84: =IF(D84<=100,Parameters!$B$6,IF(D84<=500,Parameters!$B$7,IF(D84<=2000,Parameters!$B$8,IF(D84<=10000,Parameters!$B$9,Parameters!$B$10)))) -> 2000 | L84: =I84+J84+K84 -> 6464.9 | M84: =H84-J84 -> 6210 | N84: =H84-L84 -> 1365.1 | O84: =O83+N84 -> -3190.95 | P84: =IF(H84<>0,M84/H84,0) -> 0.79310345 | Q84: =IF(H84<>0,N84/H84,0) -> 0.17434227 | R84: =Parameters!$D$22 -> 29 | S84: =Parameters!$D$20 -> 6 | T84: =Parameters!$D$14 -> 55 | U84: =IF(Parameters!$D$17<>0,(Parameters!$D$22-Parameters!$D$20)/Parameters!$D$17,0) -> 575 | V84: =IF((Parameters!$D$22-Parameters!$D$20)>0,Parameters!$D$14/(Parameters!$D$22-Parameters!$D$20),999) -> 2.3913043 | W84: =IF(Parameters!$D$14<>0,IF(Parameters!$D$17<>0,(Parameters!$D$22-Parameters!$D$20)/(Parameters!$D$17*Parameters!$D$14),0),0) -> 10.454545 | X84: =IF(O84>=0,1,0) -> 0
...

Sheet Fixed_Cost_Tiers
A1: Users Range | B1: Fixed Cost/mo | C1: Rationale
A2: 0 – 100 | B2: $1,000 | C2: Solo founder + basic infra
A3: 101 – 500 | B3: $1500 | C3: Part-time hire or infra upgrade
A4: 501 – 2,000 | B4: $4,000 | C4: 2nd person + scaling servers
A5: 2,001 – 10,000 | B5: $8,000 | C5: Small team 3–4 people
A6: 10,000+ | B6: $15,000 | C6: Ops + eng + support team

Sheet DAX_Guide
A1: Step | B1: DAX / Instructions
A2: 1. Load file | B2: Power BI Desktop → Get Data → Excel Workbook → select this file → check Monthly_Data → Load
A3: 2. Scenario slicer | B3: Add Slicer visual → field: Monthly_Data[Scenario] Filters all charts: Pessimistic / Base Case / Optimistic
A4: 3. Breakeven Month | B4: New Measure: Breakeven Month = CALCULATE(MIN(Monthly_Data[Month]), Monthly_Data[Breakeven_Flag] = 1)
A5: 4. Total Revenue | B5: New Measure: Total Revenue = SUM(Monthly_Data[Revenue_USD])
A6: 5. Total Cost | B6: New Measure: Total Cost = SUM(Monthly_Data[Total_Cost_USD])
A7: 6. Final Cumulative PnL | B7: New Measure: Final PnL = CALCULATE(MAX(Monthly_Data[Cumulative_PnL_USD]), Monthly_Data[Month] = MAX(Monthly_Data[Month]))
A8: 7. LTV/CAC (last month) | B8: New Measure: LTV CAC Ratio = CALCULATE(MAX(Monthly_Data[LTV_CAC_Ratio]), Monthly_Data[Month] = MAX(Monthly_Data[Month]))
A9: 8. Chart: Cumulative P&L | B9: Line Chart → X: Month → Y: Cumulative_PnL_USD → Legend: Scenario Analytics pane → Constant Line → value 0
A10: 9. Chart: Revenue vs Cost | B10: Line Chart → X: Month → Y: Revenue_USD + Total_Cost_USD → Legend: Scenario
A11: 10. Chart: Users Growth | B11: Area Chart → X: Month → Y: Users_Paid → Legend: Scenario
A12: 11. Chart: Monthly P&L | B12: Column Chart → X: Month → Y: Monthly_PnL_USD → Legend: Scenario
... A15: 14. Update parameters | B15: Edit yellow cells in Parameters sheet → Save Excel Power BI: Home → Refresh → all scenarios recalculate
